---
layout:     post
title:      "Promise 是个好东西，可我为啥就是不会！！"
subtitle:   "这次掉到了一个大坑里，不好往出爬额 :-)"
date:       2018-12-13
author:     "Han Qizheng"
header-img: "img/Promise.png"
tags:
    - Node.js
    - 掉坑日记
---

# 我需要学会Promise.all()大法的奥义


## 坑位复现
这次项目里的某个需求

由于我不太会优化代码（严肃），所以代码中出现了`forEach`套`await`的情况，just like this

```js
async function Print(item) {
  setTimeout(() => {
    console.log(item, new Date().getTime())
  }, 2000)
}

async function dd() {
  console.log(2, new Date().getTime())
  await a.map(item => Print(item))
  console.log(3, new Date().getTime())

}

const a = ['a', 'a', 'a', 'a']
console.log(1, new Date().getTime())
dd()
console.log(4, new Date().getTime())
```
这是我抽象出来的问题复现代码，大概就是这么个逻辑(这段代码是可以执行的)，我在所有有疑惑的地方都打了log，但是结果果然不尽人意

```js
// 实际
1 1544780465143
2 1544780465144
4 1544780465145
3 1544780465146
a 1544780467149
a 1544780467149
a 1544780467149
a 1544780467149

// 期待
1 2 a a a a 3 4
```
可以发现有两个问题
- 一个是`a a a a`执行的时间在`3 4`之后。
- 另一个是`3 4`位置竟然不对！

先来解决`3`, `4`位置不对这个问题

> 先声明，由于是个人理解，如果有错误，一定要告诉我，极度感谢

3在4之后的罪魁祸首是`async function`

在这个`async function`中，确实是`console.log('2')`，然后等待`Print()`执行，然后再`console.log('3')`

但是我忽略了一个问题就是他是一个异步函数，他已经被仍在`别的地方`去执行了，紧接着就要执行`console.log('4')`

然后当`console.log('3')`等到`Print()`，就自然打印了，当然，由于`Print()`内部`setTimeout()`,这个`console.log('3')`的打印肯定是在2s以后的事情了，自然在`console.log('4')`后面

## 怎么解决呢？

## 3 4 顺序颠倒
由于`dd()`是一个`async function()`所以他返回一个`Promise`对象，所以我们可以用`then()`来解决这个问题。

```js
dd().then(() => {
  console.log(4, new Date().getTime())
})
```
这样就解决了这个`4` 在`3` 的前面这个问题了

## aaaa的顺序错误
接下来是aaaa的顺序问题，这可以说是今天 **我写这篇blog的最终目的**

为了阅读方便，我再贴一边代码，当然是已经修复了第一个问题的

```js
async function Print(item) {
  setTimeout(() => {
    console.log(item, new Date().getTime())
  }, 2000)
}

async function dd() {
  console.log(2, new Date().getTime())
  await a.map(item => Print(item))
  console.log(3, new Date().getTime())

}

const a = ['a', 'a', 'a', 'a']
console.log(1, new Date().getTime())
dd().then(() => {
  console.log(4, new Date().getTime())
})
```
**重点**

> 再次申明，如果解释错误一定要告诉我 qq: 357571432

为什么会出现这个问题呢？都已经用await等待了，却还是出现了异步的问题

其实把这个问题产生的原因不恰当的描述一下就可以描述成 **await 管辖不了异步中的异步**

什么意思呢？

就是这里的`await Print()`只能做到，让他下面的`console.log(3)`等待其执行完毕，却无法让`console.log(3)`等待`Print()`内部的`setTimeout()`(异步)也执行完毕！

所以要解决这个问题，就要请出今天的主角 **Promis.all()**

`Promise.all()`接受一个`Promise`数组作为参数

而这个数组是什么意思呢？

意思就是我现在有一堆`Promise`，我要等他们都执行完才能执行下面的语句。当然，`Promise.all()`要搭配`await`使用。

那么上述的代码怎么修改？

首先我们肯定是要把问题的根源`Print()`用`Promise.all()`包住
```js
await Promise.all(Print())
```

但是这么写是**不对**的，因为`Promise.all()`接受一个`Promise`数组作为参数，所以我们要让`Print()`返回一个`Promise数组`。

```js
async function Print(item) {
  return new Promise((resolve, reject) => {
    setTimeout(() => {
      console.log(item, new Date().getTime())
      resolve()
    }, 2000)
  })
}
```
这里要插播一下`Promise`相关的知识

大家都知道`Promise`要从`pending --->  fulfilled` 或 `pending --->  rejected`

`resolve()`函数可以让`pending --->  fulfilled`

然后就变成了最终这个样子

```js
async function Print(item) {
  return new Promise((resolve, reject) => {
    setTimeout(() => {
      console.log(item, new Date().getTime())
      resolve()
    }, 2000)
  })
}

async function dd() {
  console.log(2, new Date().getTime())
  await Promise.all(a.map(item => Print(item)))
  console.log(3, new Date().getTime())
}

const a = ['a', 'a', 'a', 'a']
console.log(1, new Date().getTime())
dd().then(() => {
  console.log(4, new Date().getTime())
})
```
在来试一下结果
```
1 1544784166268
2 1544784166270
a 1544784168273
a 1544784168274
a 1544784168274
a 1544784168274
3 1544784168274
4 1544784168275
```
一切ok





